Workbook
Name Intrinsic_Value_Per_Share: DCF_valuation!$B$12

Sheet Cover
B10: Company | C10: Tata Consultancy Services Ltd.
B11: NSE Symbol | C11: TCS
B12: Industry | C12: Information Technology Services
B13: Currency | C13: INR (₹ Crores)
B14: Valuation Date | C14: (Today's Date)
B15: Forecast Period | C15: FY25–FY29
B16: Terminal Growth Model | C16: Gordon Growth Model

Sheet Assumptions
A1: ASSUMPTIONS
A4: GENERAL INFORMATION
A5: PARAMETER | B5: VALUE | C5: REMARKS
A6: Company Name | B6: Tata Consultancy Ltd. | C6: NSE:TCS
A7: Currency | B7: INR(Crores) | C7: Financial Statements
A8: Historical Period | B8: FY21-FY24 | C8: Actual Financials
A9: Forecast Period | B9: FY25-FY29 | C9: Projected Financials
A10: Valuation Date | B10: 46226 | C10: Model Date
A11: Valuation Method | B11: FCFF, DCF | C11: Gordon Growth Method
A12: Base Year | B12: FY26 | C12: Latest Actual Year
A14: REVENUE & OPERATING ASSUMPTIONS
A15: PARAMETER | B15: VALUE | C15: FORMULA/SOURCE
A16: Historical Revenue CAGR | B16: =Historical_Financials!B35 -> 0.10216501 | C16: From FY21/FY24
A17: Forecast Revenue Growth | B17: =AVERAGE('Forecast Assumptions'!B6:F6) -> 0.057 | C17: e.g.,8%
A18: EBIT Margin | B18: =Historical_Financials!B36 -> 0.24866599 | C18: % of Revenue
A19: Effective Tax Rate | B19: =Historical_Financials!B37 -> 0.24914644 | C19: avg. historical tax rate
A20: Depreciation(% of Revenue) | B20: =Historical_Financials!B39 -> 0.022181899 | C20: Historical average
A21: CapEx(% of Revenue) | B21: =Historical_Financials!B41 -> 0.014830907 | C21: Historical average
A22: Net Working Capital (% of Revenue) | B22: =Historical_Financials!B43 -> 0.20827534 | C22: Historical average
A24: CAPM INPUTS
A25: PARAMETER | B25: VALUE | C25: REMARKS
A26: Risk Free Rate | B26: ='CAPM & WACC'!B6 -> 0.0618 | C26: Government Bond Yield
A27: Beta | B27: ='CAPM & WACC'!B7 -> 0.24 | C27: Levered Beta
A28: Market Risk Premium | B28: ='CAPM & WACC'!B9 -> 0.0623 | C28: Market Return-Risk Free Rate
A30: COST OF DEBT
A31: PARAMETER | B31: VALUE | C31: REMARKS
A32: Interest Expense | B32: ='CAPM & WACC'!B14 -> 1227
A33: Total Debt | B33: ='CAPM & WACC'!B15 -> 11283
A34: Pre-tax Cost of Debt | B34: ='CAPM & WACC'!B16 -> 0.10874767 | C34: Interest /Debt
A35: After tax Cost of Debt | B35: ='CAPM & WACC'!B18 -> 0.081560755 | C35: Pre-tax Cost * (1-Tax Rate)
A37: CAPITAL STRUCTURE
A38: PARAMETER | B38: VALUE
A39: Market Value of Equity | B39: ='CAPM & WACC'!B22 -> 814500
A40: Market Value of Debt | B40: ='CAPM & WACC'!B23 -> 11283
A41: Equity Weight | B41: ='CAPM & WACC'!B25 -> 0.99406126
A42: Debt Weight | B42: ='CAPM & WACC'!B26 -> 0.013770403
A44: WACC
A45: PARAMETER | B45: VALUE
A46: Cost of Equity | B46: ='CAPM & WACC'!B30 -> 0.076752
A47: After-tax Cost of Debt | B47: ='CAPM & WACC'!B31 -> 0.081560755
...

Sheet Historical_Financials
A1: HISTORICAL FINANCIALS
A4: INCOME STATEMENT
A5: PARTICULARS | B5: FY26 | C5: FY25 | D5: FY24 | E5: FY23 | F5: FY22 | G5: FY21
A6: REVENUE | B6: 267021 | C6: 255324 | D6: 240893 | E6: 225458 | F6: 191754 | G6: 164177
A7: REVENUE GROWTH(%) | B7: =(B6/C6)-1 -> 0.04581238 | C7: =(C6/D6)-1 -> 0.059906265 | D7: =(D6/E6)-1 -> 0.068460645 | E7: =(E6/F6)-1 -> 0.17576687 | F7: =(F6/G6)-1 -> 0.16797115
A8: EBIT | B8: 66838 | C8: 62165 | D8: 59311 | E8: 54237 | F8: 48453 | G8: 42481
A9: EBIT MARGIN(%) | B9: =B8/B6 -> 0.2503099 | C9: =C8/C6 -> 0.24347496 | D9: =D8/D6 -> 0.24621305 | E9: =E8/E6 -> 0.24056365 | F9: =F8/F6 -> 0.25268313 | G9: =G8/G6 -> 0.25875123
A10: PROFIT BEFORE TAX(PBT) | B10: 70355 | C10: 65331 | D10: 63038 | E10: 56907 | F10: 51687 | G10: 44978
A11: TAX EXPENSE | B11: 16033 | C11: 16534 | D11: 15898 | E11: 14604 | F11: 13238 | G11: 11198
A12: EFFECTIVE TAX RATE(%) | B12: =B11/B10 -> 0.22788714 | C12: =C11/C10 -> 0.25308047 | D12: =D11/D10 -> 0.25219709 | E12: =E11/E10 -> 0.25662924 | F12: =F11/F10 -> 0.25611856 | G12: =G11/G10 -> 0.24896616
A13: PROFIT AFTER TAX(PAT) | B13: 52820 | C13: 48553 | D13: 46585 | E13: 42147 | F13: 38327 | G13: 33388
A14: NOPAT | B14: =B8*(1-B12) -> 51606.479 | C14: =C8*(1-C12) -> 46432.253 | D14: =D8*(1-D12) -> 44352.939 | E14: =E8*(1-E12) -> 40318.2 | F14: =F8*(1-F12) -> 36043.287 | G14: =G8*(1-G12) -> 31904.669
A16: CASH FLOW DRIVERS
A17: PARTICULARS | B17: FY26 | C17: FY25 | D17: FY24 | E17: FY23 | F17: FY22 | G17: FY21
A18: DEPRECIATION AMORTIZATION | B18: 5560 | C18: 5242 | D18: 4985 | E18: 5022 | F18: 4604 | G18: 4065
A19: CAPITAL EXPENDITURE | B19: 4037 | C19: 3861 | D19: 2644 | E19: 2887 | F19: 2995 | G19: 3176
A20: NET WORKING CAPITAL | B20: =B26-B28 -> 74791 | C20: =C26-C28 -> 70010 | D20: =D26-D28 -> 40689 | E20: =E26-E28 -> 30819 | F20: =F26-F28 -> 36321 | G20: =G26-G28 -> 32891
A21: CHANGE IN WORKING CAPITAL | B21: =B20-C20 -> 4781 | C21: =C20-D20 -> 29321 | D21: =D20-E20 -> 9870 | E21: =E20-F20 -> -5502 | F21: =F20-G20 -> 3430 | G21: =G20-H20 -> 32891
A22: FREE CASH FLOW TO FIRM(FCFF) | B22: =B14+B18-B19-B21 -> 48348.479 | C22: =C14+C18-C19-C21 -> 18492.253 | D22: =D14+D18-D19-D21 -> 36823.939 | E22: =E14+E18-E19-E21 -> 47955.2 | F22: =F14+F18-F19-F21 -> 34222.287 | G22: =G14+G18-G19-G21 -> -97.331495
A24: BALANCE SHEET DRIVERS
A25: PARTICULARS | B25: FY26 | C25: FY25 | D25: FY24 | E25: FY23 | F25: FY22 | G25: FY21
A26: TOTAL CURRENT ASETS | B26: 135705 | C26: 123011 | D26: 113610 | E26: 92784 | F26: 94192 | G26: 83160
A27: TOTAL ASSETS | B27: 182372 | C27: 159629 | D27: 174158 | E27: 152700 | F27: 149627 | G27: 128035
A28: TOTAL CURRENT LIABILITIES | B28: 60914 | C28: 53001 | D28: 72921 | E28: 61965 | F28: 57871 | G28: 50269
A29: CASH & CASH EQUIVALENTS | B29: 6417 | C29: 8342 | D29: 4907 | E29: 1462 | F29: 8197 | G29: 1112
A30: TOTAL DEBT | B30: 11283 | C30: 9392 | D30: 5604 | E30: 5364 | F30: 5335 | G30: 5406
A31: SHAREHOLDERS' EQUITY | B31: 108478 | C31: 95771 | D31: 156916 | E31: 136812 | F31: 127925 | G31: 115156
A33: KEY RATIOS
A34: PARTICULARS | B34: FY26 | C34: FY25 | D34: FY24 | E34: FY23 | F34: FY22 | G34: FY21
A35: Revenue CAGR | B35: =((B6/G6)^(1/5))-1 -> 0.10216501
A36: Average EBIT Margin | B36: =AVERAGE(B9:G9) -> 0.24866599
A37: Average Tax Rate | B37: =AVERAGE(B12:G12) -> 0.24914644
A38: Average D&A / Revenue | B38: =B18/B6 -> 0.020822332 | C38: =C18/C6 -> 0.020530777 | D38: =D18/D6 -> 0.020693835 | E38: =E18/E6 -> 0.022274659 | F38: =F18/F6 -> 0.024009929 | G38: =G18/G6 -> 0.024759863
A39: Average Depreciation (% Revenue) | B39: =AVERAGE(B38:G38) -> 0.022181899
A40: Average CapEx / Revenue | B40: =B19/B6 -> 0.015118661 | C40: =C19/C6 -> 0.015121963 | D40: =D19/D6 -> 0.010975827 | E40: =E19/E6 -> 0.012805046 | F40: =F19/F6 -> 0.01561897 | G40: =G19/G6 -> 0.019344975
A41: Average CapEx (% Revenue) | B41: =AVERAGE(B40:G40) -> 0.014830907
A42: Average NWC / Revenue | B42: =B20/B6 -> 0.28009407 | C42: =C20/C6 -> 0.27420062 | D42: =D20/D6 -> 0.16890902 | E42: =E20/E6 -> 0.13669508 | F42: =F20/F6 -> 0.18941456 | G42: =G20/G6 -> 0.20033866
A43: Average NWC (% Revenue) | B43: =AVERAGE(B42:G42) -> 0.20827534

Sheet Forecast Assumptions
A1: FORECAST DRIVERS
A4: REVENUE
A5: DRIVER | B5: FY27 | C5: FY28 | D5: FY29 | E5: FY30 | F5: FY31
A6: REVENUE GROWTH | B6: 0.06 | C6: 0.06 | D6: 0.0575 | E6: 0.055 | F6: 0.0525
A8: OPERATING PERFORMANCE
A9: DRIVER | B9: FY27 | C9: FY28 | D9: FY29 | E9: FY30 | F9: FY31
A10: EBIT MARGIN | B10: 0.25 | C10: 0.25 | D10: 0.25 | E10: 0.25 | F10: 0.25
A11: TAX RATE | B11: 0.25 | C11: 0.25 | D11: 0.25 | E11: 0.25 | F11: 0.25
A13: INVESTMENT ASSUMPTIONS
A14: DRIVER | B14: FY27 | C14: FY28 | D14: FY29 | E14: FY30 | F14: FY31
A15: DEPRECIATION(% REVENUE) | B15: 0.021 | C15: 0.021 | D15: 0.021 | E15: 0.021 | F15: 0.021
A16: CapEx(% REVENUE) | B16: 0.014 | C16: 0.014 | D16: 0.014 | E16: 0.014 | F16: 0.014
A17: NWC(% REVENUE) | B17: 0.18 | C17: 0.18 | D17: 0.18 | E17: 0.18 | F17: 0.18
A19: TERMINAL GROWTH
A20: DRIVER | B20: VALUE
A21: TERMINAL GROWTH RATE | B21: 0.035

Sheet Projected Financial statements
A1: PROJECTED FINANCIAL STATEMENT
A5: Particular | B5: FY27 | C5: FY28 | D5: FY29 | E5: FY30 | F5: FY31
A6: Revenue | B6: =Historical_Financials!B6*(1+'Forecast Assumptions'!B6) -> 283042.26 | C6: =B6*(1+'Forecast Assumptions'!C6) -> 300024.8 | D6: =C6*(1+'Forecast Assumptions'!D6) -> 317276.22 | E6: =D6*(1+'Forecast Assumptions'!E6) -> 334726.41 | F6: =E6*(1+'Forecast Assumptions'!F6) -> 352299.55
A7: EBIT | B7: =Historical_Financials!B6*'Forecast Assumptions'!B10 -> 66755.25 | C7: =Historical_Financials!C6*'Forecast Assumptions'!C10 -> 63831 | D7: =Historical_Financials!D6*'Forecast Assumptions'!D10 -> 60223.25 | E7: =Historical_Financials!E6*'Forecast Assumptions'!E10 -> 56364.5 | F7: =Historical_Financials!F6*'Forecast Assumptions'!F10 -> 47938.5
A8: Tax | B8: =Historical_Financials!B8*'Forecast Assumptions'!B11 -> 16709.5 | C8: =Historical_Financials!C8*'Forecast Assumptions'!C11 -> 15541.25 | D8: =Historical_Financials!D8*'Forecast Assumptions'!D11 -> 14827.75 | E8: =Historical_Financials!E8*'Forecast Assumptions'!E11 -> 13559.25 | F8: =Historical_Financials!F8*'Forecast Assumptions'!F11 -> 12113.25
A9: NOPAT | B9: =B7-B8 -> 50045.75 | C9: =C7-C8 -> 48289.75 | D9: =D7-D8 -> 45395.5 | E9: =E7-E8 -> 42805.25 | F9: =F7-F8 -> 35825.25
A10: Depreciation | B10: =Historical_Financials!B6*'Forecast Assumptions'!B15 -> 5607.441 | C10: =Historical_Financials!C6*'Forecast Assumptions'!C15 -> 5361.804 | D10: =Historical_Financials!D6*'Forecast Assumptions'!D15 -> 5058.753 | E10: =Historical_Financials!E6*'Forecast Assumptions'!E15 -> 4734.618 | F10: =Historical_Financials!F6*'Forecast Assumptions'!F15 -> 4026.834
A11: CapEx | B11: =Historical_Financials!B6*'Forecast Assumptions'!B16 -> 3738.294 | C11: =Historical_Financials!C6*'Forecast Assumptions'!C16 -> 3574.536 | D11: =Historical_Financials!D6*'Forecast Assumptions'!D16 -> 3372.502 | E11: =Historical_Financials!E6*'Forecast Assumptions'!E16 -> 3156.412 | F11: =Historical_Financials!F6*'Forecast Assumptions'!F16 -> 2684.556
A12: NWC | B12: =Historical_Financials!B6*'Forecast Assumptions'!B17 -> 48063.78 | C12: =Historical_Financials!C6*'Forecast Assumptions'!C17 -> 45958.32 | D12: =Historical_Financials!D6*'Forecast Assumptions'!D17 -> 43360.74 | E12: =Historical_Financials!E6*'Forecast Assumptions'!E17 -> 40582.44 | F12: =Historical_Financials!F6*'Forecast Assumptions'!F17 -> 34515.72

Sheet FCFF
A1: FREE CASH FLOW TO FIRM
A4: Particular | B4: FY27 | C4: FY28 | D4: FY29 | E4: FY30 | F4: FY31
A5: NOPAT | B5: ='Projected Financial statements'!B9 -> 50045.75 | C5: ='Projected Financial statements'!C9 -> 48289.75 | D5: ='Projected Financial statements'!D9 -> 45395.5 | E5: ='Projected Financial statements'!E9 -> 42805.25 | F5: ='Projected Financial statements'!F9 -> 35825.25
A6: Depreciation & Amortization | B6: ='Projected Financial statements'!B10 -> 5607.441 | C6: ='Projected Financial statements'!C10 -> 5361.804 | D6: ='Projected Financial statements'!D10 -> 5058.753 | E6: ='Projected Financial statements'!E10 -> 4734.618 | F6: ='Projected Financial statements'!F10 -> 4026.834
A7: Capital Expenditure | B7: ='Projected Financial statements'!B11 -> 3738.294 | C7: ='Projected Financial statements'!C11 -> 3574.536 | D7: ='Projected Financial statements'!D11 -> 3372.502 | E7: ='Projected Financial statements'!E11 -> 3156.412 | F7: ='Projected Financial statements'!F11 -> 2684.556
A8: Change in Net Working Capital | B8: ='Projected Financial statements'!B12-Historical_Financials!B21 -> 43282.78 | C8: ='Projected Financial statements'!C12-'Projected Financial statements'!B12 -> -2105.46 | D8: ='Projected Financial statements'!D12-'Projected Financial statements'!C12 -> -2597.58 | E8: ='Projected Financial statements'!E12-'Projected Financial statements'!D12 -> -2778.3 | F8: ='Projected Financial statements'!F12-'Projected Financial statements'!E12 -> -6066.72
A9: Free Cash Flow to Firm (FCFF) | B9: =B5+B6-B7-B8 -> 8632.117 | C9: =C5+C6-C7-C8 -> 52182.478 | D9: =D5+D6-D7-D8 -> 49679.331 | E9: =E5+E6-E7-E8 -> 47161.756 | F9: =F5+F6-F7-F8 -> 43234.248
A10: Discount Factor | B10: =1/(1+Assumptions!B67)^1 -> 0.92816039 | C10: =1/(1+Assumptions!B67)^2 -> 0.8614817 | D10: =1/(1+Assumptions!B67)^3 -> 0.79959319 | E10: =1/(1+Assumptions!B67)^4 -> 0.74215072 | F10: =1/(1+Assumptions!B67)^5 -> 0.6888349
A11: Present value of FCFF | B11: =B9*B10 -> 8011.989 | C11: =C9*C10 -> 44954.25 | D11: =D9*D10 -> 39723.255 | E11: =E9*E10 -> 35001.131 | F11: =F9*F10 -> 29781.259

Sheet CAPM & WACC
A1: CAPM AND WACC
A4: A) COST OF EQUITY
A5: PARTICULAR | B5: VALUE
A6: Risk-Free Rate | B6: 0.0618
A7: Beta | B7: 0.24
A8: Market Return | B8: 0.1241
A9: Equity Market Risk Premium | B9: =B8-B6 -> 0.0623
A10: Cost of Equity | B10: =B6+B7*B9 -> 0.076752
A12: B) COST OF DEBT
A13: PARTICULAR | B13: VALUE
A14: Interest Expense | B14: 1227
A15: Total Debt | B15: 11283
A16: Pre-tax Cost of Debt | B16: =B14/B15 -> 0.10874767
A17: Tax Rate | B17: 0.25
A18: After-tax Cost of Debt | B18: =B16*(1-B17) -> 0.081560755
A20: C) CAPITAL STRUCTURE
A21: PARTICULAR | B21: VALUE
A22: Market Value of Equity | B22: 814500
A23: Market Value of Debt | B23: =Historical_Financials!B30 -> 11283
A24: Enterprise Value | B24: =B22+B23-Historical_Financials!B29 -> 819366
A25: Equity Weight | B25: =B22/B24 -> 0.99406126
A26: Debt Weight | B26: =B23/B24 -> 0.013770403
A28: D) WACC
A29: PARTICULAR | B29: VALUE
A30: Cost of Equity | B30: =B10 -> 0.076752
A31: After-tax Cost of Debt | B31: =B18 -> 0.081560755
A32: Equity Weight | B32: =B25 -> 0.99406126
A33: Debt Weight | B33: =B26 -> 0.013770403
A34: Weighted Average Cost of Capital (WACC) | B34: =(B30*B32)+(B31*B33) -> 0.077419314

Sheet Terminal_value
A1: TERMINAL VALUE
A4: PARTICULAR | B4: VALUE | C4: FORMULA
A5: Terminal Year FCFF | B5: =FCFF!F9 -> 43234.248
A6: WACC | B6: ='CAPM & WACC'!B34 -> 0.077419314
A7: Terminal Growth Rate(g) | B7: 0.035 | C7: Reason-conservative and widely accepted
A8: Terminal Value | B8: =(B5*(1+B7))/(B6-B7) -> 1054883.8 | C8: (Terminal Year FCFF*(1+g))/(WACC-g)
A9: Discount Factor | B9: =1/(1+B6)^5 -> 0.68877316 | C9: 1/(1+WACC)^5
A10: Present Value of Terminal Value | B10: =B8*B9 -> 726575.64 | C10: Terminal Value*Discount Factor

Sheet DCF_valuation
A1: DCF VALUATION
A4: PARTICULAR | B4: VALUE | C4: FORMULA
A5: Present Value of Explicit FCFF | B5: =SUM(FCFF!B11:F11) -> 157471.88 | C5: SUM OF PV OF FCFF
A6: Present Value of Terminal Value | B6: =Terminal_value!B10 -> 726575.64
A7: Enterprise Value | B7: =B5+B6 -> 884047.52 | C7: PV of Explicit FCFF+ PV of Terminal Value
A8: Less: Total Debt | B8: =Historical_Financials!B30 -> 11283
A9: Add: Cash & Cash Equivalents | B9: =Historical_Financials!B29 -> 6417
A10: Equity Value | B10: =B7-B8+B9 -> 879181.52 | C10: Enterprise Value-Total Debt +Cash & Cash Eq
A11: Shares Outstanding(Crores) | B11: 361.80875
A12: Intrinsic Value Per Share(₹) | B12: =B10/B11 -> 2429.962 | C12: Equity value/Shares Outstanding

Sheet Scenario Summary
B2: Scenario Summary
D3: Current Values: | E3: Bear Case | F3: Conservative | G3: Base Case | H3: Optimistic Case | I3: Bull Case
E4: Created by Dinesh Kumar on 26-07-2026 | F4: Created by Dinesh Kumar on 26-07-2026 | G4: Created by Dinesh Kumar on 26-07-2026 | H4: Created by Dinesh Kumar on 26-07-2026 | I4: Created by Dinesh Kumar on 26-07-2026
B5: Changing Cells:
C6: $J$5 | D6: 0.085 | E6: 0.03 | F6: 0.085 | G6: 0.0774 | H6: 0.075 | I6: 0.07
C7: $J$6 | D7: 0.0325 | E7: 0.085 | F7: 0.0325 | G7: 0.035 | H7: 0.0375 | I7: 0.04
B9: Notes: Current Values column represents values of changing cells at
B10: time Scenario Summary Report was created. Changing cells for each
B11: scenario are highlighted in gray.

Sheet Sensitivity_Analysis
A1: SENSTIVITY ANALYSIS | I1: wacc | J1: =Terminal_value!B6 -> 0.077419314
I2: terminal growth | J2: =Terminal_value!B7 -> 0.035
I3: intrinsic value | J3: =( SUM(FCFF!B11:F11) + ((FCFF!F9*(1+$J$2))/($J$1-$J$2))/(1+$J$1)^5 -Historical_Financials!B30 +Historical_Financials!B29 ) /DCF_valuation!B11 -> 2429.962
A5: =J3 -> 2429.962 | B5: 0.03 | C5: 0.0325 | D5: 0.035 | E5: 0.0375 | F5: 0.04
A6: 0.07 | B6: 2615.6373 | C6: 2767.574 | D6: 2941.2158 | E6: 3141.5718 | F6: 3375.3205
A7: 0.075 | B7: 2326.9451 | C7: 2443.9094 | D7: 2575.4943 | E7: 2724.6239 | F7: 2895.0577
A8: 0.0774 | B8: 2210.4258 | C8: 2314.599 | D8: 2431.0569 | E8: 2562.1084 | F8: 2710.6803
A9: 0.08 | B9: 2097.1042 | C9: 2189.5591 | D9: 2292.2869 | E9: 2407.1002 | F9: 2536.2652
A10: 0.085 | B10: 1910.0319 | C10: 1984.685 | D10: 2066.8034 | E10: 2157.5659 | F10: 2258.4131

Sheet Dashboard
A1: TATA CONSULTANCY SERVICES
P2: =(Intrinsic_Value_Per_Share/2307)-1 -> 0.053299525 | R2: DRIVER
A3: DCF VALUATION | P3: =IF(P2>0.15,"BUY", IF(P2<-0.15,"SELL","HOLD")) -> HOLD | R3: REVENUE GROWTH
R5: DRIVER | S5: FY22 | T5: FY23 | U5: FY24 | V5: FY25 | W5: FY26 | X5: FY27 | Y5: FY28 | Z5: FY29 | AA5: FY30 | AB5: FY31
R6: REVENUE | S6: =(Historical_Financials!F6/Historical_Financials!G6)-1 -> 0.16797115 | T6: =(Historical_Financials!E6/Historical_Financials!F6)-1 -> 0.17576687 | U6: =(Historical_Financials!D6/Historical_Financials!E6)-1 -> 0.068460645 | V6: =(Historical_Financials!C6/Historical_Financials!D6)-1 -> 0.059906265 | W6: =(Historical_Financials!B6/Historical_Financials!C6)-1 -> 0.04581238 | X6: 0.06 | Y6: 0.06 | Z6: 0.0575 | AA6: 0.055 | AB6: 0.0525
